Workbook
Name Slicer_Departments: #N/A
Name Slicer_Name_Month: #N/A
Name Slicer_Year: #N/A

Sheet Dataset
A1: Year | B1: Month | C1: Name Month | D1: Departments | E1: Influx of New Clients | F1: Regular Clients | G1: Sales | H1: Costs | I1: Bathroom-I | J1: Bedroom-I | K1: Kitchen-I | L1: Living-I | M1: Garden-I | N1: Decor-I | O1: Bathroom-S | P1: Bedroom-S | Q1: Kitchen-S | R1: Living-S | S1: Garden-S | T1: Decor-S | U1: Average Check | V1: Product 1 | W1: Product 2 | X1: Product 3 | Y1: Product 4 | Z1: Product 5 | AA1: Product 6 | AB1: Product 7 | AC1: Product 8 | AD1: Product 9 | AE1: Product 10
A2: 2025 | B2: 1 | C2: JAN | D2: Northern District | E2: 77 | F2: 0.58 | G2: 96,25 | H2: 27,25 | I2: 59 | J2: 107 | K2: 53 | L2: 92 | M2: 79 | N2: 59 | O2: 130 | P2: 116 | Q2: 65 | R2: 104 | S2: 32 | T2: 77 | U2: 25 | V2: 441 | W2: 77 | X2: 357 | Y2: 183 | Z2: 97 | AA2: 10 | AB2: 422 | AC2: 29 | AD2: 71 | AE2: 40
A3: 2025 | B3: 1 | C3: JAN | D3: Eastern District | E3: 54 | F3: 0.41 | G3: 67,5 | H3: 25,15 | I3: 70 | J3: 108 | K3: 96 | L3: 132 | M3: 66 | N3: 83 | O3: 78 | P3: 96 | Q3: 60 | R3: 94 | S3: 63 | T3: 92 | U3: 26 | V3: 281 | W3: 354 | X3: 695 | Y3: 8 | Z3: 18 | AA3: 61 | AB3: 316 | AC3: 353 | AD3: 44 | AE3: 65
A4: 2025 | B4: 1 | C4: JAN | D4: Southern District | E4: 104 | F4: 0.57 | G4: 130 | H4: 17,3 | I4: 78 | J4: 102 | K4: 41 | L4: 116 | M4: 49 | N4: 103 | O4: 100 | P4: 114 | Q4: 138 | R4: 104 | S4: 33 | T4: 94 | U4: 19 | V4: 345 | W4: 159 | X4: 375 | Y4: 162 | Z4: 139 | AA4: 93 | AB4: 136 | AC4: 220 | AD4: 82 | AE4: 172
A5: 2025 | B5: 1 | C5: JAN | D5: Western District | E5: 45 | F5: 0.75 | G5: 56,25 | H5: 31 | I5: 57 | J5: 51 | K5: 84 | L5: 139 | M5: 68 | N5: 91 | O5: 73 | P5: 116 | Q5: 50 | R5: 61 | S5: 66 | T5: 34 | U5: 30 | V5: 415 | W5: 151 | X5: 677 | Y5: 108 | Z5: 104 | AA5: 107 | AB5: 656 | AC5: 28 | AD5: 104 | AE5: 75
A6: 2025 | B6: 2 | C6: FEB | D6: Northern District | E6: 64 | F6: 0.52 | G6: 80 | H6: 40,95 | I6: 49 | J6: 38 | K6: 87 | L6: 145 | M6: 50 | N6: 77 | O6: 129 | P6: 114 | Q6: 114 | R6: 104 | S6: 30 | T6: 89 | U6: 24 | V6: 380 | W6: 44 | X6: 517 | Y6: 79 | Z6: 98 | AA6: 159 | AB6: 174 | AC6: 142 | AD6: 344 | AE6: 15
A7: 2025 | B7: 2 | C7: FEB | D7: Eastern District | E7: 22 | F7: 0.37 | G7: 27,5 | H7: 58,8 | I7: 82 | J7: 53 | K7: 80 | L7: 58 | M7: 60 | N7: 110 | O7: 50 | P7: 123 | Q7: 70 | R7: 82 | S7: 54 | T7: 70 | U7: 65 | V7: 86 | W7: 99 | X7: 557 | Y7: 253 | Z7: 126 | AA7: 120 | AB7: 290 | AC7: 159 | AD7: 267 | AE7: 44
A8: 2025 | B8: 2 | C8: FEB | D8: Southern District | E8: 67 | F8: 0.8 | G8: 83,75 | H8: 35,7 | I8: 31 | J8: 57 | K8: 75 | L8: 145 | M8: 52 | N8: 119 | O8: 56 | P8: 114 | Q8: 63 | R8: 77 | S8: 32 | T8: 78 | U8: 51 | V8: 33 | W8: 358 | X8: 37 | Y8: 321 | Z8: 273 | AA8: 131 | AB8: 416 | AC8: 18 | AD8: 170 | AE8: 48
A9: 2025 | B9: 2 | C9: FEB | D9: Western District | E9: 27 | F9: 0.46 | G9: 33,75 | H9: 14,7 | I9: 68 | J9: 50 | K9: 64 | L9: 144 | M9: 78 | N9: 104 | O9: 88 | P9: 86 | Q9: 53 | R9: 46 | S9: 55 | T9: 90 | U9: 40 | V9: 322 | W9: 32 | X9: 950 | Y9: 111 | Z9: 126 | AA9: 58 | AB9: 586 | AC9: 50 | AD9: 54 | AE9: 179
A10: 2025 | B10: 3 | C10: MAR | D10: Northern District | E10: 22 | F10: 0.31 | G10: 27,5 | H10: 24,15 | I10: 47 | J10: 110 | K10: 53 | L10: 113 | M10: 55 | N10: 78 | O10: 135 | P10: 115 | Q10: 58 | R10: 99 | S10: 55 | T10: 87 | U10: 51 | V10: 39 | W10: 164 | X10: 505 | Y10: 41 | Z10: 196 | AA10: 81 | AB10: 542 | AC10: 56 | AD10: 164 | AE10: 119
A11: 2025 | B11: 3 | C11: MAR | D11: Eastern District | E11: 58 | F11: 0.48 | G11: 72,5 | H11: 39,9 | I11: 31 | J11: 71 | K11: 103 | L11: 103 | M11: 109 | N11: 128 | O11: 115 | P11: 106 | Q11: 99 | R11: 87 | S11: 63 | T11: 41 | U11: 33 | V11: 33 | W11: 160 | X11: 45 | Y11: 136 | Z11: 313 | AA11: 37 | AB11: 146 | AC11: 46 | AD11: 292 | AE11: 16
A12: 2025 | B12: 3 | C12: MAR | D12: Southern District | E12: 46 | F12: 0.77 | G12: 57,5 | H12: 18,9 | I12: 71 | J12: 113 | K12: 44 | L12: 68 | M12: 96 | N12: 97 | O12: 47 | P12: 77 | Q12: 113 | R12: 48 | S12: 67 | T12: 55 | U12: 54 | V12: 53 | W12: 8 | X12: 97 | Y12: 160 | Z12: 166 | AA12: 76 | AB12: 80 | AC12: 324 | AD12: 152 | AE12: 38
A13: 2025 | B13: 3 | C13: MAR | D13: Western District | E13: 50 | F13: 0.4 | G13: 62,5 | H13: 43,05 | I13: 32 | J13: 55 | K13: 61 | L13: 108 | M13: 67 | N13: 72 | O13: 131 | P13: 75 | Q13: 55 | R13: 49 | S13: 67 | T13: 37 | U13: 22 | V13: 314 | W13: 46 | X13: 72 | Y13: 80 | Z13: 78 | AA13: 259 | AB13: 514 | AC13: 199 | AD13: 21 | AE13: 6
A14: 2025 | B14: 4 | C14: APR | D14: Northern District | E14: 78 | F14: 0.78 | G14: 97,5 | H14: 33,6 | I14: 73 | J14: 90 | K14: 95 | L14: 124 | M14: 77 | N14: 44 | O14: 83 | P14: 103 | Q14: 64 | R14: 48 | S14: 53 | T14: 67 | U14: 57 | V14: 88 | W14: 51 | X14: 65 | Y14: 63 | Z14: 132 | AA14: 96 | AB14: 310 | AC14: 69 | AD14: 227 | AE14: 187
A15: 2025 | B15: 4 | C15: APR | D15: Eastern District | E15: 64 | F15: 0.43 | G15: 80 | H15: 22,05 | I15: 73 | J15: 56 | K15: 40 | L15: 105 | M15: 60 | N15: 59 | O15: 101 | P15: 127 | Q15: 150 | R15: 89 | S15: 70 | T15: 59 | U15: 63 | V15: 235 | W15: 105 | X15: 690 | Y15: 45 | Z15: 336 | AA15: 176 | AB15: 312 | AC15: 56 | AD15: 35 | AE15: 141
A16: 2025 | B16: 4 | C16: APR | D16: Southern District | E16: 48 | F16: 0.34 | G16: 60 | H16: 55,65 | I16: 76 | J16: 97 | K16: 100 | L16: 74 | M16: 88 | N16: 93 | O16: 76 | P16: 124 | Q16: 91 | R16: 90 | S16: 38 | T16: 43 | U16: 18 | V16: 130 | W16: 46 | X16: 395 | Y16: 188 | Z16: 126 | AA16: 69 | AB16: 30 | AC16: 93 | AD16: 86 | AE16: 186
A17: 2025 | B17: 4 | C17: APR | D17: Western District | E17: 70 | F17: 0.36 | G17: 87,5 | H17: 51,45 | I17: 47 | J17: 107 | K17: 62 | L17: 85 | M17: 46 | N17: 47 | O17: 68 | P17: 116 | Q17: 52 | R17: 58 | S17: 65 | T17: 58 | U17: 102 | V17: 87 | W17: 63 | X17: 485 | Y17: 109 | Z17: 56 | AA17: 83 | AB17: 676 | AC17: 63 | AD17: 206 | AE17: 79
A18: 2025 | B18: 5 | C18: MAY | D18: Northern District | E18: 33 | F18: 0.66 | G18: 41,25 | H18: 25,2 | I18: 43 | J18: 77 | K18: 96 | L18: 104 | M18: 59 | N18: 99 | O18: 129 | P18: 88 | Q18: 60 | R18: 86 | S18: 37 | T18: 95 | U18: 92 | V18: 85 | W18: 122 | X18: 285 | Y18: 115 | Z18: 397 | AA18: 100 | AB18: 46 | AC18: 34 | AD18: 243 | AE18: 54
A19: 2025 | B19: 5 | C19: MAY | D19: Eastern District | E19: 48 | F19: 0.51 | G19: 60 | H19: 39,9 | I19: 81 | J19: 62 | K19: 60 | L19: 50 | M19: 90 | N19: 64 | O19: 83 | P19: 80 | Q19: 104 | R19: 86 | S19: 29 | T19: 66 | U19: 31 | V19: 50 | W19: 360 | X19: 102 | Y19: 339 | Z19: 186 | AA19: 27 | AB19: 100 | AC19: 16 | AD19: 40 | AE19: 19
A20: 2025 | B20: 5 | C20: MAY | D20: Southern District | E20: 66 | F20: 0.52 | G20: 82,5 | H20: 46,2 | I20: 72 | J20: 85 | K20: 99 | L20: 78 | M20: 92 | N20: 63 | O20: 54 | P20: 89 | Q20: 70 | R20: 101 | S20: 54 | T20: 81 | U20: 21 | V20: 189 | W20: 324 | X20: 512 | Y20: 44 | Z20: 139 | AA20: 143 | AB20: 86 | AC20: 56 | AD20: 149 | AE20: 53
A21: 2025 | B21: 5 | C21: MAY | D21: Western District | E21: 45 | F21: 0.7 | G21: 56,25 | H21: 49,35 | I21: 64 | J21: 40 | K21: 88 | L21: 120 | M21: 112 | N21: 47 | O21: 55 | P21: 45 | Q21: 53 | R21: 86 | S21: 41 | T21: 45 | U21: 76 | V21: 374 | W21: 96 | X21: 220 | Y21: 198 | Z21: 219 | AA21: 130 | AB21: 432 | AC21: 83 | AD21: 130 | AE21: 120
A22: 2025 | B22: 6 | C22: JUN | D22: Northern District | E22: 86 | F22: 0.52 | G22: 107,5 | H22: 24,15 | I22: 28 | J22: 50 | K22: 105 | L22: 117 | M22: 108 | N22: 44 | O22: 76 | P22: 87 | Q22: 53 | R22: 97 | S22: 39 | T22: 67 | U22: 106 | V22: 28 | W22: 147 | X22: 265 | Y22: 59 | Z22: 54 | AA22: 98 | AB22: 212 | AC22: 35 | AD22: 39 | AE22: 23
A23: 2025 | B23: 6 | C23: JUN | D23: Eastern District | E23: 74 | F23: 0.51 | G23: 92,5 | H23: 51,45 | I23: 79 | J23: 51 | K23: 88 | L23: 104 | M23: 78 | N23: 105 | O23: 128 | P23: 54 | Q23: 95 | R23: 72 | S23: 46 | T23: 71 | U23: 117 | V23: 85 | W23: 106 | X23: 72 | Y23: 136 | Z23: 393 | AA23: 23 | AB23: 352 | AC23: 38 | AD23: 157 | AE23: 83
A24: 2025 | B24: 6 | C24: JUN | D24: Southern District | E24: 46 | F24: 0.37 | G24: 57,5 | H24: 12,6 | I24: 60 | J24: 103 | K24: 72 | L24: 60 | M24: 61 | N24: 50 | O24: 71 | P24: 114 | Q24: 88 | R24: 86 | S24: 30 | T24: 38 | U24: 27 | V24: 312 | W24: 89 | X24: 470 | Y24: 132 | Z24: 308 | AA24: 40 | AB24: 386 | AC24: 242 | AD24: 64 | AE24: 25
A25: 2025 | B25: 6 | C25: JUN | D25: Western District | E25: 30 | F25: 0.58 | G25: 37,5 | H25: 12,6 | I25: 70 | J25: 39 | K25: 40 | L25: 140 | M25: 49 | N25: 47 | O25: 115 | P25: 50 | Q25: 55 | R25: 39 | S25: 26 | T25: 97 | U25: 70 | V25: 354 | W25: 222 | X25: 562 | Y25: 337 | Z25: 101 | AA25: 35 | AB25: 194 | AC25: 21 | AD25: 119 | AE25: 8
A26: 2025 | B26: 7 | C26: JUL | D26: Northern District | E26: 102 | F26: 0.76 | G26: 127,5 | H26: 28,35 | I26: 39 | J26: 79 | K26: 71 | L26: 131 | M26: 101 | N26: 128 | O26: 46 | P26: 101 | Q26: 75 | R26: 87 | S26: 41 | T26: 73 | U26: 120 | V26: 206 | W26: 144 | X26: 195 | Y26: 39 | Z26: 76 | AA26: 57 | AB26: 188 | AC26: 364 | AD26: 21 | AE26: 118
A27: 2025 | B27: 7 | C27: JUL | D27: Eastern District | E27: 84 | F27: 0.6 | G27: 105 | H27: 44,1 | I27: 66 | J27: 75 | K27: 88 | L27: 77 | M27: 100 | N27: 97 | O27: 79 | P27: 91 | Q27: 124 | R27: 94 | S27: 49 | T27: 73 | U27: 25 | V27: 202 | W27: 76 | X27: 395 | Y27: 10 | Z27: 53 | AA27: 119 | AB27: 240 | AC27: 282 | AD27: 116 | AE27: 68
A28: 2025 | B28: 7 | C28: JUL | D28: Southern District | E28: 54 | F28: 0.44 | G28: 67,5 | H28: 56,7 | I28: 37 | J28: 86 | K28: 101 | L28: 113 | M28: 55 | N28: 92 | O28: 134 | P28: 74 | Q28: 133 | R28: 74 | S28: 68 | T28: 96 | U28: 125 | V28: 319 | W28: 80 | X28: 172 | Y28: 108 | Z28: 122 | AA28: 86 | AB28: 152 | AC28: 25 | AD28: 220 | AE28: 165
A29: 2025 | B29: 7 | C29: JUL | D29: Western District | E29: 100 | F29: 0.79 | G29: 125 | H29: 42 | I29: 61 | J29: 112 | K29: 94 | L29: 104 | M29: 52 | N29: 122 | O29: 112 | P29: 62 | Q29: 148 | R29: 51 | S29: 35 | T29: 69 | U29: 110 | V29: 182 | W29: 315 | X29: 17 | Y29: 15 | Z29: 214 | AA29: 75 | AB29: 752 | AC29: 84 | AD29: 158 | AE29: 182
A30: 2025 | B30: 8 | C30: AUG | D30: Northern District | E30: 90 | F30: 0.55 | G30: 112,5 | H30: 55,65 | I30: 80 | J30: 89 | K30: 44 | L30: 113 | M30: 44 | N30: 45 | O30: 134 | P30: 110 | Q30: 126 | R30: 52 | S30: 46 | T30: 88 | U30: 38 | V30: 232 | W30: 40 | X30: 192 | Y30: 30 | Z30: 241 | AA30: 263 | AB30: 452 | AC30: 95 | AD30: 62 | AE30: 53
A31: 2025 | B31: 8 | C31: AUG | D31: Eastern District | E31: 98 | F31: 0.34 | G31: 122,5 | H31: 43,05 | I31: 58 | J31: 65 | K31: 53 | L31: 134 | M31: 93 | N31: 125 | O31: 125 | P31: 63 | Q31: 142 | R31: 53 | S31: 56 | T31: 91 | U31: 68 | V31: 85 | W31: 138 | X31: 110 | Y31: 39 | Z31: 140 | AA31: 135 | AB31: 594 | AC31: 76 | AD31: 164 | AE31: 31
A32: 2025 | B32: 8 | C32: AUG | D32: Southern District | E32: 89 | F32: 0.3 | G32: 111,25 | H32: 33,6 | I32: 50 | J32: 97 | K32: 97 | L32: 110 | M32: 102 | N32: 122 | O32: 115 | P32: 123 | Q32: 87 | R32: 50 | S32: 58 | T32: 94 | U32: 112 | V32: 104 | W32: 116 | X32: 730 | Y32: 334 | Z32: 44 | AA32: 86 | AB32: 124 | AC32: 162 | AD32: 184 | AE32: 23
A33: 2025 | B33: 8 | C33: AUG | D33: Western District | E33: 75 | F33: 0.71 | G33: 93,75 | H33: 32,55 | I33: 47 | J33: 63 | K33: 80 | L33: 121 | M33: 60 | N33: 124 | O33: 98 | P33: 85 | Q33: 79 | R33: 38 | S33: 50 | T33: 94 | U33: 102 | V33: 39 | W33: 205 | X33: 197 | Y33: 49 | Z33: 150 | AA33: 276 | AB33: 422 | AC33: 56 | AD33: 205 | AE33: 9
A34: 2025 | B34: 9 | C34: SEP | D34: Northern District | E34: 72 | F34: 0.43 | G34: 90 | H34: 29,4 | I34: 78 | J34: 85 | K34: 78 | L34: 83 | M34: 54 | N34: 86 | O34: 60 | P34: 62 | Q34: 57 | R34: 71 | S34: 64 | T34: 46 | U34: 96 | V34: 417 | W34: 28 | X34: 275 | Y34: 359 | Z34: 192 | AA34: 149 | AB34: 50 | AC34: 200 | AD34: 9 | AE34: 20
A35: 2025 | B35: 9 | C35: SEP | D35: Eastern District | E35: 52 | F35: 0.54 | G35: 65 | H35: 58,8 | I35: 51 | J35: 107 | K35: 66 | L35: 96 | M35: 85 | N35: 78 | O35: 124 | P35: 60 | Q35: 59 | R35: 79 | S35: 30 | T35: 70 | U35: 36 | V35: 136 | W35: 315 | X35: 725 | Y35: 80 | Z35: 199 | AA35: 90 | AB35: 320 | AC35: 44 | AD35: 207 | AE35: 11
A36: 2025 | B36: 9 | C36: SEP | D36: Southern District | E36: 56 | F36: 0.51 | G36: 70 | H36: 58,8 | I36: 29 | J36: 88 | K36: 39 | L36: 119 | M36: 90 | N36: 70 | O36: 56 | P36: 61 | Q36: 130 | R36: 43 | S36: 55 | T36: 97 | U36: 96 | V36: 343 | W36: 284 | X36: 190 | Y36: 120 | Z36: 288 | AA36: 48 | AB36: 148 | AC36: 98 | AD36: 131 | AE36: 60
A37: 2025 | B37: 9 | C37: SEP | D37: Western District | E37: 40 | F37: 0.79 | G37: 50 | H37: 30,45 | I37: 63 | J37: 99 | K37: 35 | L37: 85 | M37: 71 | N37: 67 | O37: 62 | P37: 126 | Q37: 122 | R37: 50 | S37: 60 | T37: 75 | U37: 52 | V37: 417 | W37: 141 | X37: 840 | Y37: 187 | Z37: 100 | AA37: 86 | AB37: 44 | AC37: 56 | AD37: 160 | AE37: 50
A38: 2025 | B38: 10 | C38: OCT | D38: Northern District | E38: 74 | F38: 0.69 | G38: 92,5 | H38: 29,4 | I38: 67 | J38: 99 | K38: 40 | L38: 80 | M38: 93 | N38: 111 | O38: 134 | P38: 111 | Q38: 126 | R38: 60 | S38: 60 | T38: 56 | U38: 134 | V38: 172 | W38: 54 | X38: 937 | Y38: 98 | Z38: 211 | AA38: 215 | AB38: 44 | AC38: 68 | AD38: 21 | AE38: 25
A39: 2025 | B39: 10 | C39: OCT | D39: Eastern District | E39: 22 | F39: 0.46 | G39: 27,5 | H39: 56,7 | I39: 36 | J39: 77 | K39: 90 | L39: 90 | M39: 39 | N39: 68 | O39: 90 | P39: 106 | Q39: 68 | R39: 69 | S39: 53 | T39: 77 | U39: 78 | V39: 159 | W39: 4 | X39: 295 | Y39: 129 | Z39: 18 | AA39: 130 | AB39: 60 | AC39: 328 | AD39: 20 | AE39: 96
A40: 2025 | B40: 10 | C40: OCT | D40: Southern District | E40: 92 | F40: 0.61 | G40: 115 | H40: 47,25 | I40: 48 | J40: 104 | K40: 88 | L40: 135 | M40: 74 | N40: 104 | O40: 57 | P40: 112 | Q40: 122 | R40: 58 | S40: 43 | T40: 80 | U40: 63 | V40: 128 | W40: 66 | X40: 115 | Y40: 180 | Z40: 183 | AA40: 183 | AB40: 440 | AC40: 98 | AD40: 158 | AE40: 47
...

Sheet Pivot
A1: Year | B1: (All) | D1: Year | E1: (All)
A3: Row Labels | B3: Sum of Influx of New Clients | D3: Row Labels | E3: Average of Regular Clients | G3: Row Labels | H3: Sum of Sales | K3: Row Labels | L3: Sum of Sales | M3: Sum of Costs | O3: Sum of Bathroom-I | P3: Sum of Bedroom-I | Q3: Sum of Kitchen-I | R3: Sum of Living-I | S3: Sum of Garden-I | T3: Sum of Decor-I | U3: Sum of Bathroom-S | V3: Sum of Bedroom-S | W3: Sum of Kitchen-S | X3: Sum of Living-S | Y3: Sum of Garden-S | Z3: Sum of Decor-S
A4: 1 | B4: 924 | D4: 1 | E4: 0.5175 | G4: 2022 | H4: 2777 | K4: JAN | L4: 846 | M4: 290 | O4: 13575 | P4: 14840 | Q4: 15033 | R4: 16196 | S4: 15026 | T4: 14953 | U4: 15376 | V4: 15303 | W4: 15865 | X4: 14686 | Y4: 13453 | Z4: 14101
A5: 2 | B5: 929 | D5: 2 | E5: 0.545625 | G5: 2023 | H5: 3827 | K5: FEB | L5: 738 | M5: 232
A6: 3 | B6: 876 | D6: 3 | E6: 0.528125 | G6: 2024 | H6: 1125 | K6: MAR | L6: 710 | M6: 198
A7: 4 | B7: 864 | D7: 4 | E7: 0.528125 | G7: 2025 | H7: 1195 | K7: APR | L7: 549 | M7: 223
A8: 5 | B8: 712 | D8: 5 | E8: 0.50625 | G8: Grand Total | H8: 8924 | K8: MAY | L8: 637 | M8: 218
A9: 6 | B9: 1020 | D9: 6 | E9: 0.51125 | K9: JUN | L9: 633 | M9: 247
A10: 7 | B10: 1167 | D10: 7 | E10: 0.55125 | K10: JUL | L10: 788 | M10: 215
A11: 8 | B11: 1260 | D11: 8 | E11: 0.48625 | K11: AUG | L11: 759 | M11: 228
A12: 9 | B12: 868 | D12: 9 | E12: 0.576875 | K12: SEP | L12: 851 | M12: 245
A13: 10 | B13: 1222 | D13: 10 | E13: 0.520625 | K13: OCT | L13: 1011 | M13: 233
A14: 11 | B14: 957 | D14: 11 | E14: 0.56625 | K14: NOV | L14: 816 | M14: 282
A15: 12 | B15: 1102 | D15: 12 | E15: 0.486875 | K15: DEC | L15: 586 | M15: 291
A16: Grand Total | B16: 11901 | D16: Grand Total | E16: 0.52708333 | K16: Grand Total | L16: 8924 | M16: 2902
A18: Year | B18: (All)
A20: Row Labels | B20: Sum of Influx of New Clients | G20: Row Labels | H20: Sum of Sales | K20: Row Labels | L20: Sum of Sales | M20: Sum of Costs
A21: 1 | B21: 924 | G21: Eastern District | H21: 2283 | K21: JAN | L21: 846 | M21: 290
A22: 2 | B22: 929 | G22: Northern District | H22: 1949 | K22: FEB | L22: 738 | M22: 232 | O22: Sum of Product 1 | P22: Sum of Product 2 | Q22: Sum of Product 3 | R22: Sum of Product 4 | S22: Sum of Product 5 | T22: Sum of Product 6 | U22: Sum of Product 7 | V22: Sum of Product 8 | W22: Sum of Product 9 | X22: Sum of Product 10
A23: 3 | B23: 876 | G23: Southern District | H23: 2568 | K23: MAR | L23: 710 | M23: 198 | O23: 29833 | P23: 30756 | Q23: 44257 | R23: 28948 | S23: 28255 | T23: 25959 | U23: 33084 | V23: 23362 | W23: 29292 | X23: 26322
A24: 4 | B24: 864 | G24: Western District | H24: 2124 | K24: APR | L24: 549 | M24: 223
A25: 5 | B25: 712 | G25: Grand Total | H25: 8924 | K25: MAY | L25: 637 | M25: 218
A26: 6 | B26: 1020 | K26: JUN | L26: 633 | M26: 247
A27: 7 | B27: 1167 | G27: Row Labels | H27: Sum of Sales | K27: JUL | L27: 788 | M27: 215
A28: 8 | B28: 1260 | G28: Eastern District | H28: 2283 | K28: AUG | L28: 759 | M28: 228
A29: 9 | B29: 868 | G29: Northern District | H29: 1949 | K29: SEP | L29: 851 | M29: 245
A30: 10 | B30: 1222 | G30: Southern District | H30: 2568 | K30: OCT | L30: 1011 | M30: 233
A31: 11 | B31: 957 | G31: Western District | H31: 2124 | K31: NOV | L31: 816 | M31: 282
A32: 12 | B32: 1102 | G32: Grand Total | H32: 8924 | K32: DEC | L32: 586 | M32: 291
A33: Grand Total | B33: 11901 | K33: Grand Total | L33: 8924 | M33: 2902
G37: Row Labels | H37: Sum of Average Check
G38: JAN | H38: 809
G39: FEB | H39: 1036 | K39: Row Labels | L39: Sum of Bathroom-I | M39: Sum of Bedroom-I | N39: Sum of Kitchen-I | O39: Sum of Living-I | P39: Sum of Garden-I | Q39: Sum of Decor-I | R39: Sum of Bathroom-S | S39: Sum of Bedroom-S | T39: Sum of Kitchen-S | U39: Sum of Living-S | V39: Sum of Garden-S | W39: Sum of Decor-S
G40: MAR | H40: 920 | K40: 1 | L40: 1341 | M40: 1356 | N40: 1213 | O40: 1479 | P40: 1082 | Q40: 1075 | R40: 1214 | S40: 1333 | T40: 1227 | U40: 1243 | V40: 1191 | W40: 1243
G41: APR | H41: 1105 | K41: 2 | L41: 1173 | M41: 1261 | N41: 1313 | O41: 1510 | P41: 1156 | Q41: 1345 | R41: 1242 | S41: 1265 | T41: 1197 | U41: 1266 | V41: 1091 | W41: 1172
G42: MAY | H42: 1043 | K42: 3 | L42: 1043 | M42: 1318 | N42: 1156 | O42: 1092 | P42: 1324 | Q42: 1358 | R42: 1412 | S42: 1277 | T42: 1362 | U42: 1290 | V42: 1091 | W42: 1125
G43: JUN | H43: 1012 | K43: 4 | L43: 1193 | M43: 1216 | N43: 1287 | O43: 1293 | P43: 1174 | Q43: 1144 | R43: 1092 | S43: 1282 | T43: 1405 | U43: 1099 | V43: 1153 | W43: 1176
G44: JUL | H44: 1173 | K44: 5 | L44: 1344 | M44: 1014 | N44: 1264 | O44: 1347 | P44: 1184 | Q44: 1237 | R44: 1196 | S44: 1131 | T44: 1135 | U44: 1294 | V44: 878 | W44: 1223
G45: AUG | H45: 1144 | K45: 6 | L45: 1154 | M45: 1187 | N45: 1302 | O45: 1359 | P45: 1381 | Q45: 1315 | R45: 1349 | S45: 1220 | T45: 1256 | U45: 1218 | V45: 1057 | W45: 1260
G46: SEP | H46: 1226 | K46: 7 | L46: 902 | M46: 1113 | N46: 1428 | O46: 1465 | P46: 1181 | Q46: 1253 | R46: 1166 | S46: 1413 | T46: 1362 | U46: 1296 | V46: 1171 | W46: 1086
...

Sheet Process
B1: Influx of New Clients | G1: Regular Clients | I1: x | J1: y | L1: Total Annual Profit | N1: {=TRANSPOSE(L3:L6)} -> 2022 | O1: 2023 | P1: 2024 | Q1: 2025 | R1: Level | S1: Indica | V1: Inventory | W1: Sales | Y1: Inventory | Z1: Sales | AA1: ■ | AB1: <-- | AC1: ALT+219 | AF1: Average Check
A2: S.No | B2: Month | C2: Clients | D2: Level | E2: Indica | G2: =GETPIVOTDATA("Regular Clients",Pivot!$D$3) -> 0.52708333 | H2: =100%-G2 -> 0.47291667 | I2: =SIN(G3*2*PI()) -> -0.639439 | J2: =COS(G3*2*PI()) -> -0.76884183 | L2: Year | M2: Sales | N2: =IF(AND($L2=N$1,$R2=0),$M2,0) -> 0 | O2: =IF(AND($L2=O$1,$R2=0),$M2,0) -> 0 | P2: =IF(AND($L2=P$1,$R2=0),$M2,0) -> 0 | Q2: =IF(AND($L2=Q$1,$R2=0),$M2,0) -> 0 | R2: =IFERROR(INDEX(Pivot!$H$4:$H$7,MATCH(Process!L2,Pivot!$G$4:$G$7,0)),0) -> 0 | S2: =IF(R2=0,NA(),R2) -> #N/A | U2: Bathroom | V2: =GETPIVOTDATA(""&U2&"-I",Pivot!$O$3)*$Y$2 -> 13575 | W2: =GETPIVOTDATA(""&U2&"-S",Pivot!$O$3)*$Z$2 -> 15376 | Y2: TRUE | Z2: TRUE | AE2: Month | AF2: Value | AG2: Mark | AH2: Indica
A3: 1 | B3: Jan | C3: =GETPIVOTDATA("Influx of New Clients",Pivot!$A$3,"Month",A3) -> 924 | D3: =IFERROR(GETPIVOTDATA("Influx of New Clients",Pivot!$A$20,"Month",A3),NA()) -> 924 | E3: =IF(ISNA(D3),D3,C3) -> 924 | G3: =G2+100%/(360/30) -> 0.61041667 | H3: =100%-G3 -> 0.38958333 | L3: 2022 | M3: 2777 | N3: =IF(AND($L3=N$1,$R3=0),$M3,0) -> 0 | O3: =IF(AND($L3=O$1,$R3=0),$M3,0) -> 0 | P3: =IF(AND($L3=P$1,$R3=0),$M3,0) -> 0 | Q3: =IF(AND($L3=Q$1,$R3=0),$M3,0) -> 0 | R3: =IFERROR(INDEX(Pivot!$H$4:$H$7,MATCH(Process!L3,Pivot!$G$4:$G$7,0)),0) -> 2777 | S3: =IF(R3=0,NA(),R3) -> 2777 | U3: Bedroom | V3: =GETPIVOTDATA(""&U3&"-I",Pivot!$O$3)*$Y$2 -> 14840 | W3: =GETPIVOTDATA(""&U3&"-S",Pivot!$O$3)*$Z$2 -> 15303 | AE3: Jan | AF3: =GETPIVOTDATA("Average Check",Pivot!$G$37,"Name Month",AE3) -> 809 | AG3: =GETPIVOTDATA("Average Check",Pivot!$G$52,"Name Month",AE3) -> 809 | AH3: =IF(COUNTIF($AG$3:$AG$14,">0")=1,AG3,NA()) -> #N/A
A4: 2 | B4: Feb | C4: =GETPIVOTDATA("Influx of New Clients",Pivot!$A$3,"Month",A4) -> 929 | D4: =IFERROR(GETPIVOTDATA("Influx of New Clients",Pivot!$A$20,"Month",A4),NA()) -> 929 | E4: =IF(ISNA(D4),D4,C4) -> 929 | L4: 2023 | M4: 3827 | N4: =IF(AND($L4=N$1,$R4=0),$M4,0) -> 0 | O4: =IF(AND($L4=O$1,$R4=0),$M4,0) -> 0 | P4: =IF(AND($L4=P$1,$R4=0),$M4,0) -> 0 | Q4: =IF(AND($L4=Q$1,$R4=0),$M4,0) -> 0 | R4: =IFERROR(INDEX(Pivot!$H$4:$H$7,MATCH(Process!L4,Pivot!$G$4:$G$7,0)),0) -> 3827 | S4: =IF(R4=0,NA(),R4) -> 3827 | U4: Kitchen | V4: =GETPIVOTDATA(""&U4&"-I",Pivot!$O$3)*$Y$2 -> 15033 | W4: =GETPIVOTDATA(""&U4&"-S",Pivot!$O$3)*$Z$2 -> 15865 | Y4: =IF(Y2,AA1,"") -> ■ | Z4: =IF(Z2,AA1,"") -> ■ | AE4: Feb | AF4: =GETPIVOTDATA("Average Check",Pivot!$G$37,"Name Month",AE4) -> 1036 | AG4: =GETPIVOTDATA("Average Check",Pivot!$G$52,"Name Month",AE4) -> 1036 | AH4: =IF(COUNTIF($AG$3:$AG$14,">0")=1,AG4,NA()) -> #N/A
A5: 3 | B5: Mar | C5: =GETPIVOTDATA("Influx of New Clients",Pivot!$A$3,"Month",A5) -> 876 | D5: =IFERROR(GETPIVOTDATA("Influx of New Clients",Pivot!$A$20,"Month",A5),NA()) -> 876 | E5: =IF(ISNA(D5),D5,C5) -> 876 | L5: 2024 | M5: 1125 | N5: =IF(AND($L5=N$1,$R5=0),$M5,0) -> 0 | O5: =IF(AND($L5=O$1,$R5=0),$M5,0) -> 0 | P5: =IF(AND($L5=P$1,$R5=0),$M5,0) -> 0 | Q5: =IF(AND($L5=Q$1,$R5=0),$M5,0) -> 0 | R5: =IFERROR(INDEX(Pivot!$H$4:$H$7,MATCH(Process!L5,Pivot!$G$4:$G$7,0)),0) -> 1125 | S5: =IF(R5=0,NA(),R5) -> 1125 | U5: Living | V5: =GETPIVOTDATA(""&U5&"-I",Pivot!$O$3)*$Y$2 -> 16196 | W5: =GETPIVOTDATA(""&U5&"-S",Pivot!$O$3)*$Z$2 -> 14686 | AE5: Mar | AF5: =GETPIVOTDATA("Average Check",Pivot!$G$37,"Name Month",AE5) -> 920 | AG5: =GETPIVOTDATA("Average Check",Pivot!$G$52,"Name Month",AE5) -> 920 | AH5: =IF(COUNTIF($AG$3:$AG$14,">0")=1,AG5,NA()) -> #N/A
A6: 4 | B6: Apr | C6: =GETPIVOTDATA("Influx of New Clients",Pivot!$A$3,"Month",A6) -> 864 | D6: =IFERROR(GETPIVOTDATA("Influx of New Clients",Pivot!$A$20,"Month",A6),NA()) -> 864 | E6: =IF(ISNA(D6),D6,C6) -> 864 | L6: 2025 | M6: 1195 | N6: =IF(AND($L6=N$1,$R6=0),$M6,0) -> 0 | O6: =IF(AND($L6=O$1,$R6=0),$M6,0) -> 0 | P6: =IF(AND($L6=P$1,$R6=0),$M6,0) -> 0 | Q6: =IF(AND($L6=Q$1,$R6=0),$M6,0) -> 0 | R6: =IFERROR(INDEX(Pivot!$H$4:$H$7,MATCH(Process!L6,Pivot!$G$4:$G$7,0)),0) -> 1195 | S6: =IF(R6=0,NA(),R6) -> 1195 | U6: Garden | V6: =GETPIVOTDATA(""&U6&"-I",Pivot!$O$3)*$Y$2 -> 15026 | W6: =GETPIVOTDATA(""&U6&"-S",Pivot!$O$3)*$Z$2 -> 13453 | AE6: Apr | AF6: =GETPIVOTDATA("Average Check",Pivot!$G$37,"Name Month",AE6) -> 1105 | AG6: =GETPIVOTDATA("Average Check",Pivot!$G$52,"Name Month",AE6) -> 1105 | AH6: =IF(COUNTIF($AG$3:$AG$14,">0")=1,AG6,NA()) -> #N/A
A7: 5 | B7: May | C7: =GETPIVOTDATA("Influx of New Clients",Pivot!$A$3,"Month",A7) -> 712 | D7: =IFERROR(GETPIVOTDATA("Influx of New Clients",Pivot!$A$20,"Month",A7),NA()) -> 712 | E7: =IF(ISNA(D7),D7,C7) -> 712 | N7: =IF(AND($L7=N$1,$R7=0),$M7,0) -> 0 | O7: =IF(AND($L7=O$1,$R7=0),$M7,0) -> 0 | P7: =IF(AND($L7=P$1,$R7=0),$M7,0) -> 0 | Q7: =IF(AND($L7=Q$1,$R7=0),$M7,0) -> 0 | R7: =IFERROR(INDEX(Pivot!$H$4:$H$7,MATCH(Process!L7,Pivot!$G$4:$G$7,0)),0) -> 0 | S7: =IF(R7=0,NA(),R7) -> #N/A | U7: Decor | V7: =GETPIVOTDATA(""&U7&"-I",Pivot!$O$3)*$Y$2 -> 14953 | W7: =GETPIVOTDATA(""&U7&"-S",Pivot!$O$3)*$Z$2 -> 14101 | AE7: May | AF7: =GETPIVOTDATA("Average Check",Pivot!$G$37,"Name Month",AE7) -> 1043 | AG7: =GETPIVOTDATA("Average Check",Pivot!$G$52,"Name Month",AE7) -> 1043 | AH7: =IF(COUNTIF($AG$3:$AG$14,">0")=1,AG7,NA()) -> #N/A
A8: 6 | B8: Jun | C8: =GETPIVOTDATA("Influx of New Clients",Pivot!$A$3,"Month",A8) -> 1020 | D8: =IFERROR(GETPIVOTDATA("Influx of New Clients",Pivot!$A$20,"Month",A8),NA()) -> 1020 | E8: =IF(ISNA(D8),D8,C8) -> 1020 | V8: =SUM(V2:V7) -> 89623 | W8: =SUM(W2:W7) -> 88784 | AE8: Jun | AF8: =GETPIVOTDATA("Average Check",Pivot!$G$37,"Name Month",AE8) -> 1012 | AG8: =GETPIVOTDATA("Average Check",Pivot!$G$52,"Name Month",AE8) -> 1012 | AH8: =IF(COUNTIF($AG$3:$AG$14,">0")=1,AG8,NA()) -> #N/A
A9: 7 | B9: Jul | C9: =GETPIVOTDATA("Influx of New Clients",Pivot!$A$3,"Month",A9) -> 1167 | D9: =IFERROR(GETPIVOTDATA("Influx of New Clients",Pivot!$A$20,"Month",A9),NA()) -> 1167 | E9: =IF(ISNA(D9),D9,C9) -> 1167 | AE9: Jul | AF9: =GETPIVOTDATA("Average Check",Pivot!$G$37,"Name Month",AE9) -> 1173 | AG9: =GETPIVOTDATA("Average Check",Pivot!$G$52,"Name Month",AE9) -> 1173 | AH9: =IF(COUNTIF($AG$3:$AG$14,">0")=1,AG9,NA()) -> #N/A
A10: 8 | B10: Aug | C10: =GETPIVOTDATA("Influx of New Clients",Pivot!$A$3,"Month",A10) -> 1260 | D10: =IFERROR(GETPIVOTDATA("Influx of New Clients",Pivot!$A$20,"Month",A10),NA()) -> 1260 | E10: =IF(ISNA(D10),D10,C10) -> 1260 | AE10: Aug | AF10: =GETPIVOTDATA("Average Check",Pivot!$G$37,"Name Month",AE10) -> 1144 | AG10: =GETPIVOTDATA("Average Check",Pivot!$G$52,"Name Month",AE10) -> 1144 | AH10: =IF(COUNTIF($AG$3:$AG$14,">0")=1,AG10,NA()) -> #N/A
A11: 9 | B11: Sep | C11: =GETPIVOTDATA("Influx of New Clients",Pivot!$A$3,"Month",A11) -> 868 | D11: =IFERROR(GETPIVOTDATA("Influx of New Clients",Pivot!$A$20,"Month",A11),NA()) -> 868 | E11: =IF(ISNA(D11),D11,C11) -> 868 | L11: Departments | M11: Value | N11: Data X | O11: Data Y | P11: X | Q11: Y | U11: 1 | V11: Product 1 | W11: =GETPIVOTDATA(""&V11,Pivot!$O$22) -> 29833 | X11: {=IFERROR(INDEX($V$11:$V$20,SMALL(IF($W$11:$W$20=Y11,ROW($W$11:$W$20)-ROW($W$11)+1),COUNTIF($Y$11:Y11,Y11))),"")} -> Product 3 | Y11: =LARGE($W$11:$W$20,U11) -> 44257 | Z11: =INDEX($V$11:$V$20,MATCH(Y11,$W$11:$W$20,0)) -> Product 3 | AE11: Sep | AF11: =GETPIVOTDATA("Average Check",Pivot!$G$37,"Name Month",AE11) -> 1226 | AG11: =GETPIVOTDATA("Average Check",Pivot!$G$52,"Name Month",AE11) -> 1226 | AH11: =IF(COUNTIF($AG$3:$AG$14,">0")=1,AG11,NA()) -> #N/A
A12: 10 | B12: Oct | C12: =GETPIVOTDATA("Influx of New Clients",Pivot!$A$3,"Month",A12) -> 1222 | D12: =IFERROR(GETPIVOTDATA("Influx of New Clients",Pivot!$A$20,"Month",A12),NA()) -> 1222 | E12: =IF(ISNA(D12),D12,C12) -> 1222 | L12: Eastern District | M12: =IFERROR(GETPIVOTDATA("Sales",Pivot!$G$27,"Departments",""&L12)/GETPIVOTDATA("Sales",Pivot!$G$20),0) -> 0.25582698 | N12: =SUM($M$12:M12) -> 0.25582698 | O12: =100%-N12 -> 0.74417302 | P12: =IF(M12=0,NA(),SIN(N12*2*PI())) -> 0.99932985 | Q12: =IF(M12=0,NA(),COS(O12*2*PI())) -> -0.036603838 | U12: 2 | V12: Product 2 | W12: =GETPIVOTDATA(""&V12,Pivot!$O$22) -> 30756 | X12: {=IFERROR(INDEX($V$11:$V$20,SMALL(IF($W$11:$W$20=Y12,ROW($W$11:$W$20)-ROW($W$11)+1),COUNTIF($Y$11:Y12,Y12))),"")} -> Product 7 | Y12: =LARGE($W$11:$W$20,U12) -> 33084 | Z12: =INDEX($V$11:$V$20,MATCH(Y12,$W$11:$W$20,0)) -> Product 7 | AE12: Oct | AF12: =GETPIVOTDATA("Average Check",Pivot!$G$37,"Name Month",AE12) -> 1421 | AG12: =GETPIVOTDATA("Average Check",Pivot!$G$52,"Name Month",AE12) -> 1421 | AH12: =IF(COUNTIF($AG$3:$AG$14,">0")=1,AG12,NA()) -> #N/A
A13: 11 | B13: Nov | C13: =GETPIVOTDATA("Influx of New Clients",Pivot!$A$3,"Month",A13) -> 957 | D13: =IFERROR(GETPIVOTDATA("Influx of New Clients",Pivot!$A$20,"Month",A13),NA()) -> 957 | E13: =IF(ISNA(D13),D13,C13) -> 957 | L13: Northern District | M13: =IFERROR(GETPIVOTDATA("Sales",Pivot!$G$27,"Departments",""&L13)/GETPIVOTDATA("Sales",Pivot!$G$20),0) -> 0.21839982 | N13: =SUM($M$12:M13) -> 0.4742268 | O13: =100%-N13 -> 0.5257732 | P13: =IF(M13=0,NA(),SIN(N13*2*PI())) -> 0.16123092 | Q13: =IF(M13=0,NA(),COS(O13*2*PI())) -> -0.98691671 | U13: 3 | V13: Product 3 | W13: =GETPIVOTDATA(""&V13,Pivot!$O$22) -> 44257 | X13: {=IFERROR(INDEX($V$11:$V$20,SMALL(IF($W$11:$W$20=Y13,ROW($W$11:$W$20)-ROW($W$11)+1),COUNTIF($Y$11:Y13,Y13))),"")} -> Product 2 | Y13: =LARGE($W$11:$W$20,U13) -> 30756 | Z13: =INDEX($V$11:$V$20,MATCH(Y13,$W$11:$W$20,0)) -> Product 2 | AE13: Nov | AF13: =GETPIVOTDATA("Average Check",Pivot!$G$37,"Name Month",AE13) -> 1339 | AG13: =GETPIVOTDATA("Average Check",Pivot!$G$52,"Name Month",AE13) -> 1339 | AH13: =IF(COUNTIF($AG$3:$AG$14,">0")=1,AG13,NA()) -> #N/A
A14: 12 | B14: Dec | C14: =GETPIVOTDATA("Influx of New Clients",Pivot!$A$3,"Month",A14) -> 1102 | D14: =IFERROR(GETPIVOTDATA("Influx of New Clients",Pivot!$A$20,"Month",A14),NA()) -> 1102 | E14: =IF(ISNA(D14),D14,C14) -> 1102 | L14: Southern District | M14: =IFERROR(GETPIVOTDATA("Sales",Pivot!$G$27,"Departments",""&L14)/GETPIVOTDATA("Sales",Pivot!$G$20),0) -> 0.28776333 | N14: =SUM($M$12:M14) -> 0.76199014 | O14: =100%-N14 -> 0.23800986 | P14: =IF(M14=0,NA(),SIN(N14*2*PI())) -> -0.99716357 | Q14: =IF(M14=0,NA(),COS(O14*2*PI())) -> 0.075265023 | U14: 4 | V14: Product 4 | W14: =GETPIVOTDATA(""&V14,Pivot!$O$22) -> 28948 | X14: {=IFERROR(INDEX($V$11:$V$20,SMALL(IF($W$11:$W$20=Y14,ROW($W$11:$W$20)-ROW($W$11)+1),COUNTIF($Y$11:Y14,Y14))),"")} -> Product 1 | Y14: =LARGE($W$11:$W$20,U14) -> 29833 | Z14: =INDEX($V$11:$V$20,MATCH(Y14,$W$11:$W$20,0)) -> Product 1 | AE14: Dec | AF14: =GETPIVOTDATA("Average Check",Pivot!$G$37,"Name Month",AE14) -> 1436 | AG14: =GETPIVOTDATA("Average Check",Pivot!$G$52,"Name Month",AE14) -> 1436 | AH14: =IF(COUNTIF($AG$3:$AG$14,">0")=1,AG14,NA()) -> #N/A
C15: =SUM(C3:C14) -> 11901 | D15: {=SUM(IFERROR(D3:D14,0))} -> 11901 | L15: Western District | M15: =IFERROR(GETPIVOTDATA("Sales",Pivot!$G$27,"Departments",""&L15)/GETPIVOTDATA("Sales",Pivot!$G$20),0) -> 0.23800986 | N15: =SUM($M$12:M15) -> 1 | O15: =100%-N15 -> 0 | P15: =IF(M15=0,NA(),SIN(N15*2*PI())) -> -2.4502969e-16 | Q15: =IF(M15=0,NA(),COS(O15*2*PI())) -> 1 | U15: 5 | V15: Product 5 | W15: =GETPIVOTDATA(""&V15,Pivot!$O$22) -> 28255 | X15: {=IFERROR(INDEX($V$11:$V$20,SMALL(IF($W$11:$W$20=Y15,ROW($W$11:$W$20)-ROW($W$11)+1),COUNTIF($Y$11:Y15,Y15))),"")} -> Product 9 | Y15: =LARGE($W$11:$W$20,U15) -> 29292 | Z15: =INDEX($V$11:$V$20,MATCH(Y15,$W$11:$W$20,0)) -> Product 9 | AG15: =GETPIVOTDATA("Average Check",Pivot!$G$52) -> 13664
M16: =100%-SUM(M12:M15) -> 0 | O16: =IF(M16=0,GETPIVOTDATA("Sales",Pivot!$G$20),SUM(Process!M12:M15)) -> 8924 | P16: =IF(M16=0,NA(),0) -> #N/A | Q16: =IF(M16=0,NA(),1) -> #N/A | U16: 6 | V16: Product 6 | W16: =GETPIVOTDATA(""&V16,Pivot!$O$22) -> 25959 | X16: {=IFERROR(INDEX($V$11:$V$20,SMALL(IF($W$11:$W$20=Y16,ROW($W$11:$W$20)-ROW($W$11)+1),COUNTIF($Y$11:Y16,Y16))),"")} -> Product 4 | Y16: =LARGE($W$11:$W$20,U16) -> 28948 | Z16: =INDEX($V$11:$V$20,MATCH(Y16,$W$11:$W$20,0)) -> Product 4 | AO16: 1.4 | AS16: 0.7
U17: 7 | V17: Product 7 | W17: =GETPIVOTDATA(""&V17,Pivot!$O$22) -> 33084 | X17: {=IFERROR(INDEX($V$11:$V$20,SMALL(IF($W$11:$W$20=Y17,ROW($W$11:$W$20)-ROW($W$11)+1),COUNTIF($Y$11:Y17,Y17))),"")} -> Product 5 | Y17: =LARGE($W$11:$W$20,U17) -> 28255 | Z17: =INDEX($V$11:$V$20,MATCH(Y17,$W$11:$W$20,0)) -> Product 5 | AE17: Sales & Inventory | AG17: Sales | AH17: Inventory | AL17: Products | AM17: =AI25 -> Sales | AN17: =AJ25 -> Inventory | AO17: Left | AP17: =AI25 -> Sales | AQ17: Middle | AR17: =AJ25 -> Inventory | AS17: Right
L18: Month | M18: Sales | N18: S Layer | O18: Cost | P18: Mark | U18: 8 | V18: Product 8 | W18: =GETPIVOTDATA(""&V18,Pivot!$O$22) -> 23362 | X18: {=IFERROR(INDEX($V$11:$V$20,SMALL(IF($W$11:$W$20=Y18,ROW($W$11:$W$20)-ROW($W$11)+1),COUNTIF($Y$11:Y18,Y18))),"")} -> Product 10 | Y18: =LARGE($W$11:$W$20,U18) -> 26322 | Z18: =INDEX($V$11:$V$20,MATCH(Y18,$W$11:$W$20,0)) -> Product 10 | AE18: 1 | AF18: Bathroom | AG18: =GETPIVOTDATA($AF18&"-"&LEFT(AG$17,1),Pivot!$K$39) -> 15376 | AH18: =GETPIVOTDATA($AF18&"-"&LEFT(AH$17,1),Pivot!$K$39) -> 13575 | AL18: =AH26 -> Kitchen | AM18: =AI26 -> 15865 | AN18: =AJ26 -> 15033 | AO18: {=MAX($AM$18:$AN$23*$AO$16-AP18)} -> 6809.4 | AP18: =AI26 -> 15865 | AQ18: =MAX($AM$18:$AN$23)*$AS$16 -> 11337.2 | AR18: =AJ26 -> 15033 | AS18: {=MAX($AM$18:$AN$23*$AO$16-AR18)} -> 7641.4
L19: Jan | M19: =GETPIVOTDATA("Sum of Sales",Pivot!$K$3,"Name Month",""&L19) -> 846 | N19: =IFERROR(GETPIVOTDATA("Sum of Sales",Pivot!$K$20,"Name Month",""&L19),NA()) -> 846 | O19: =GETPIVOTDATA("Sum of Costs",Pivot!$K$3,"Name Month",""&L19) -> 290 | P19: =IF(ISNA(N19),N19,M19) -> 846 | U19: 9 | V19: Product 9 | W19: =GETPIVOTDATA(""&V19,Pivot!$O$22) -> 29292 | X19: {=IFERROR(INDEX($V$11:$V$20,SMALL(IF($W$11:$W$20=Y19,ROW($W$11:$W$20)-ROW($W$11)+1),COUNTIF($Y$11:Y19,Y19))),"")} -> Product 6 | Y19: =LARGE($W$11:$W$20,U19) -> 25959 | Z19: =INDEX($V$11:$V$20,MATCH(Y19,$W$11:$W$20,0)) -> Product 6 | AE19: 2 | AF19: Bedroom | AG19: =GETPIVOTDATA($AF19&"-"&LEFT(AG$17,1),Pivot!$K$39) -> 15303 | AH19: =GETPIVOTDATA($AF19&"-"&LEFT(AH$17,1),Pivot!$K$39) -> 14840 | AL19: =AH27 -> Bathroom | AM19: =AI27 -> 15376 | AN19: =AJ27 -> 13575 | AO19: {=MAX($AM$18:$AN$23*$AO$16-AP19)} -> 7298.4 | AP19: =AI27 -> 15376 | AQ19: =MAX($AM$18:$AN$23)*$AS$16 -> 11337.2 | AR19: =AJ27 -> 13575 | AS19: {=MAX($AM$18:$AN$23*$AO$16-AR19)} -> 9099.4
L20: Feb | M20: =GETPIVOTDATA("Sum of Sales",Pivot!$K$3,"Name Month",""&L20) -> 738 | N20: =IFERROR(GETPIVOTDATA("Sum of Sales",Pivot!$K$20,"Name Month",""&L20),NA()) -> 738 | O20: =GETPIVOTDATA("Sum of Costs",Pivot!$K$3,"Name Month",""&L20) -> 232 | P20: =IF(ISNA(N20),N20,M20) -> 738 | U20: 10 | V20: Product 10 | W20: =GETPIVOTDATA(""&V20,Pivot!$O$22) -> 26322 | X20: {=IFERROR(INDEX($V$11:$V$20,SMALL(IF($W$11:$W$20=Y20,ROW($W$11:$W$20)-ROW($W$11)+1),COUNTIF($Y$11:Y20,Y20))),"")} -> Product 8 | Y20: =LARGE($W$11:$W$20,U20) -> 23362 | Z20: =INDEX($V$11:$V$20,MATCH(Y20,$W$11:$W$20,0)) -> Product 8 | AE20: 3 | AF20: Kitchen | AG20: =GETPIVOTDATA($AF20&"-"&LEFT(AG$17,1),Pivot!$K$39) -> 15865 | AH20: =GETPIVOTDATA($AF20&"-"&LEFT(AH$17,1),Pivot!$K$39) -> 15033 | AL20: =AH28 -> Bedroom | AM20: =AI28 -> 15303 | AN20: =AJ28 -> 14840 | AO20: {=MAX($AM$18:$AN$23*$AO$16-AP20)} -> 7371.4 | AP20: =AI28 -> 15303 | AQ20: =MAX($AM$18:$AN$23)*$AS$16 -> 11337.2 | AR20: =AJ28 -> 14840 | AS20: {=MAX($AM$18:$AN$23*$AO$16-AR20)} -> 7834.4
L21: Mar | M21: =GETPIVOTDATA("Sum of Sales",Pivot!$K$3,"Name Month",""&L21) -> 710 | N21: =IFERROR(GETPIVOTDATA("Sum of Sales",Pivot!$K$20,"Name Month",""&L21),NA()) -> 710 | O21: =GETPIVOTDATA("Sum of Costs",Pivot!$K$3,"Name Month",""&L21) -> 198 | P21: =IF(ISNA(N21),N21,M21) -> 710 | AE21: 4 | AF21: Living | AG21: =GETPIVOTDATA($AF21&"-"&LEFT(AG$17,1),Pivot!$K$39) -> 14686 | AH21: =GETPIVOTDATA($AF21&"-"&LEFT(AH$17,1),Pivot!$K$39) -> 16196 | AL21: =AH29 -> Living | AM21: =AI29 -> 14686 | AN21: =AJ29 -> 16196 | AO21: {=MAX($AM$18:$AN$23*$AO$16-AP21)} -> 7988.4 | AP21: =AI29 -> 14686 | AQ21: =MAX($AM$18:$AN$23)*$AS$16 -> 11337.2 | AR21: =AJ29 -> 16196 | AS21: {=MAX($AM$18:$AN$23*$AO$16-AR21)} -> 6478.4
L22: Apr | M22: =GETPIVOTDATA("Sum of Sales",Pivot!$K$3,"Name Month",""&L22) -> 549 | N22: =IFERROR(GETPIVOTDATA("Sum of Sales",Pivot!$K$20,"Name Month",""&L22),NA()) -> 549 | O22: =GETPIVOTDATA("Sum of Costs",Pivot!$K$3,"Name Month",""&L22) -> 223 | P22: =IF(ISNA(N22),N22,M22) -> 549 | V22: Top 5 Product | W22: Value | X22: Mark | Y22: 1.3 | AE22: 5 | AF22: Garden | AG22: =GETPIVOTDATA($AF22&"-"&LEFT(AG$17,1),Pivot!$K$39) -> 13453 | AH22: =GETPIVOTDATA($AF22&"-"&LEFT(AH$17,1),Pivot!$K$39) -> 15026 | AL22: =AH30 -> Decor | AM22: =AI30 -> 14101 | AN22: =AJ30 -> 14953 | AO22: {=MAX($AM$18:$AN$23*$AO$16-AP22)} -> 8573.4 | AP22: =AI30 -> 14101 | AQ22: =MAX($AM$18:$AN$23)*$AS$16 -> 11337.2 | AR22: =AJ30 -> 14953 | AS22: {=MAX($AM$18:$AN$23*$AO$16-AR22)} -> 7721.4
L23: May | M23: =GETPIVOTDATA("Sum of Sales",Pivot!$K$3,"Name Month",""&L23) -> 637 | N23: =IFERROR(GETPIVOTDATA("Sum of Sales",Pivot!$K$20,"Name Month",""&L23),NA()) -> 637 | O23: =GETPIVOTDATA("Sum of Costs",Pivot!$K$3,"Name Month",""&L23) -> 218 | P23: =IF(ISNA(N23),N23,M23) -> 637 | U23: 1 | V23: =X11 -> Product 3 | W23: =Y11 -> 44257 | X23: =$W$23*$Y$22-W23 -> 13277.1 | AE23: 6 | AF23: Decor | AG23: =GETPIVOTDATA($AF23&"-"&LEFT(AG$17,1),Pivot!$K$39) -> 14101 | AH23: =GETPIVOTDATA($AF23&"-"&LEFT(AH$17,1),Pivot!$K$39) -> 14953 | AL23: =AH31 -> Garden | AM23: =AI31 -> 13453 | AN23: =AJ31 -> 15026 | AO23: {=MAX($AM$18:$AN$23*$AO$16-AP23)} -> 9221.4 | AP23: =AI31 -> 13453 | AQ23: =MAX($AM$18:$AN$23)*$AS$16 -> 11337.2 | AR23: =AJ31 -> 15026 | AS23: {=MAX($AM$18:$AN$23*$AO$16-AR23)} -> 7648.4
L24: Jun | M24: =GETPIVOTDATA("Sum of Sales",Pivot!$K$3,"Name Month",""&L24) -> 633 | N24: =IFERROR(GETPIVOTDATA("Sum of Sales",Pivot!$K$20,"Name Month",""&L24),NA()) -> 633 | O24: =GETPIVOTDATA("Sum of Costs",Pivot!$K$3,"Name Month",""&L24) -> 247 | P24: =IF(ISNA(N24),N24,M24) -> 633 | U24: 2 | V24: =X12 -> Product 7 | W24: =Y12 -> 33084 | X24: =$W$23*$Y$22-W24 -> 24450.1
L25: Jul | M25: =GETPIVOTDATA("Sum of Sales",Pivot!$K$3,"Name Month",""&L25) -> 788 | N25: =IFERROR(GETPIVOTDATA("Sum of Sales",Pivot!$K$20,"Name Month",""&L25),NA()) -> 788 | O25: =GETPIVOTDATA("Sum of Costs",Pivot!$K$3,"Name Month",""&L25) -> 215 | P25: =IF(ISNA(N25),N25,M25) -> 788 | U25: 3 | V25: =X13 -> Product 2 | W25: =Y13 -> 30756 | X25: =$W$23*$Y$22-W25 -> 26778.1 | AE25: Sort by Sales | AI25: =AG17 -> Sales | AJ25: =AH17 -> Inventory | AL25: Sort by Inventory | AP25: =AH17 -> Inventory | AQ25: =AG17 -> Sales
L26: Aug | M26: =GETPIVOTDATA("Sum of Sales",Pivot!$K$3,"Name Month",""&L26) -> 759 | N26: =IFERROR(GETPIVOTDATA("Sum of Sales",Pivot!$K$20,"Name Month",""&L26),NA()) -> 759 | O26: =GETPIVOTDATA("Sum of Costs",Pivot!$K$3,"Name Month",""&L26) -> 228 | P26: =IF(ISNA(N26),N26,M26) -> 759 | U26: 4 | V26: =X14 -> Product 1 | W26: =Y14 -> 29833 | X26: =$W$23*$Y$22-W26 -> 27701.1 | AE26: 1 | AF26: =AG18 -> 15376 | AG26: =AF18 -> Bathroom | AH26: {=IFERROR(INDEX($AG$26:$AG$31,SMALL(IF($AF$26:$AF$31=AI26,ROW($AF$26:$AF$31)-ROW($AF$26)+1),COUNTIF($AI$26:AI26, AI26))),"")} -> Kitchen | AI26: =LARGE($AF$26:$AF$31,AE26) -> 15865 | AJ26: =INDEX($AH$18:$AH$23,MATCH(AI26,$AG$18:$AG$23,0)) -> 15033 | AL26: 1 | AM26: =AH18 -> 13575 | AN26: =AF18 -> Bathroom | AO26: {=IFERROR(INDEX($AN$26:$AN$31,SMALL(IF($AM$26:$AM$31=AP26,ROW($AM$26:$AM$31)-ROW($AM$26)+1),COUNTIF($AP$26:AP26, AP26))),"")} -> Living | AP26: =LARGE($AM$26:$AM$31,AL26) -> 16196 | AQ26: =INDEX($AG$18:$AG$23,MATCH(AP26,$AH$18:$AH$23,0)) -> 14686
L27: Sep | M27: =GETPIVOTDATA("Sum of Sales",Pivot!$K$3,"Name Month",""&L27) -> 851 | N27: =IFERROR(GETPIVOTDATA("Sum of Sales",Pivot!$K$20,"Name Month",""&L27),NA()) -> 851 | O27: =GETPIVOTDATA("Sum of Costs",Pivot!$K$3,"Name Month",""&L27) -> 245 | P27: =IF(ISNA(N27),N27,M27) -> 851 | U27: 5 | V27: =X15 -> Product 9 | W27: =Y15 -> 29292 | X27: =$W$23*$Y$22-W27 -> 28242.1 | AE27: 2 | AF27: =AG19 -> 15303 | AG27: =AF19 -> Bedroom | AH27: {=IFERROR(INDEX($AG$26:$AG$31,SMALL(IF($AF$26:$AF$31=AI27,ROW($AF$26:$AF$31)-ROW($AF$26)+1),COUNTIF($AI$26:AI27, AI27))),"")} -> Bathroom | AI27: =LARGE($AF$26:$AF$31,AE27) -> 15376 | AJ27: =INDEX($AH$18:$AH$23,MATCH(AI27,$AG$18:$AG$23,0)) -> 13575 | AL27: 2 | AM27: =AH19 -> 14840 | AN27: =AF19 -> Bedroom | AO27: {=IFERROR(INDEX($AN$26:$AN$31,SMALL(IF($AM$26:$AM$31=AP27,ROW($AM$26:$AM$31)-ROW($AM$26)+1),COUNTIF($AP$26:AP27, AP27))),"")} -> Kitchen | AP27: =LARGE($AM$26:$AM$31,AL27) -> 15033 | AQ27: =INDEX($AG$18:$AG$23,MATCH(AP27,$AH$18:$AH$23,0)) -> 15865
L28: Oct | M28: =GETPIVOTDATA("Sum of Sales",Pivot!$K$3,"Name Month",""&L28) -> 1011 | N28: =IFERROR(GETPIVOTDATA("Sum of Sales",Pivot!$K$20,"Name Month",""&L28),NA()) -> 1011 | O28: =GETPIVOTDATA("Sum of Costs",Pivot!$K$3,"Name Month",""&L28) -> 233 | P28: =IF(ISNA(N28),N28,M28) -> 1011 | AE28: 3 | AF28: =AG20 -> 15865 | AG28: =AF20 -> Kitchen | AH28: {=IFERROR(INDEX($AG$26:$AG$31,SMALL(IF($AF$26:$AF$31=AI28,ROW($AF$26:$AF$31)-ROW($AF$26)+1),COUNTIF($AI$26:AI28, AI28))),"")} -> Bedroom | AI28: =LARGE($AF$26:$AF$31,AE28) -> 15303 | AJ28: =INDEX($AH$18:$AH$23,MATCH(AI28,$AG$18:$AG$23,0)) -> 14840 | AL28: 3 | AM28: =AH20 -> 15033 | AN28: =AF20 -> Kitchen | AO28: {=IFERROR(INDEX($AN$26:$AN$31,SMALL(IF($AM$26:$AM$31=AP28,ROW($AM$26:$AM$31)-ROW($AM$26)+1),COUNTIF($AP$26:AP28, AP28))),"")} -> Garden | AP28: =LARGE($AM$26:$AM$31,AL28) -> 15026 | AQ28: =INDEX($AG$18:$AG$23,MATCH(AP28,$AH$18:$AH$23,0)) -> 13453
L29: Nov | M29: =GETPIVOTDATA("Sum of Sales",Pivot!$K$3,"Name Month",""&L29) -> 816 | N29: =IFERROR(GETPIVOTDATA("Sum of Sales",Pivot!$K$20,"Name Month",""&L29),NA()) -> 816 | O29: =GETPIVOTDATA("Sum of Costs",Pivot!$K$3,"Name Month",""&L29) -> 282 | P29: =IF(ISNA(N29),N29,M29) -> 816 | AE29: 4 | AF29: =AG21 -> 14686 | AG29: =AF21 -> Living | AH29: {=IFERROR(INDEX($AG$26:$AG$31,SMALL(IF($AF$26:$AF$31=AI29,ROW($AF$26:$AF$31)-ROW($AF$26)+1),COUNTIF($AI$26:AI29, AI29))),"")} -> Living | AI29: =LARGE($AF$26:$AF$31,AE29) -> 14686 | AJ29: =INDEX($AH$18:$AH$23,MATCH(AI29,$AG$18:$AG$23,0)) -> 16196 | AL29: 4 | AM29: =AH21 -> 16196 | AN29: =AF21 -> Living | AO29: {=IFERROR(INDEX($AN$26:$AN$31,SMALL(IF($AM$26:$AM$31=AP29,ROW($AM$26:$AM$31)-ROW($AM$26)+1),COUNTIF($AP$26:AP29, AP29))),"")} -> Decor | AP29: =LARGE($AM$26:$AM$31,AL29) -> 14953 | AQ29: =INDEX($AG$18:$AG$23,MATCH(AP29,$AH$18:$AH$23,0)) -> 14101
L30: Dec | M30: =GETPIVOTDATA("Sum of Sales",Pivot!$K$3,"Name Month",""&L30) -> 586 | N30: =IFERROR(GETPIVOTDATA("Sum of Sales",Pivot!$K$20,"Name Month",""&L30),NA()) -> 586 | O30: =GETPIVOTDATA("Sum of Costs",Pivot!$K$3,"Name Month",""&L30) -> 291 | P30: =IF(ISNA(N30),N30,M30) -> 586 | AE30: 5 | AF30: =AG22 -> 13453 | AG30: =AF22 -> Garden | AH30: {=IFERROR(INDEX($AG$26:$AG$31,SMALL(IF($AF$26:$AF$31=AI30,ROW($AF$26:$AF$31)-ROW($AF$26)+1),COUNTIF($AI$26:AI30, AI30))),"")} -> Decor | AI30: =LARGE($AF$26:$AF$31,AE30) -> 14101 | AJ30: =INDEX($AH$18:$AH$23,MATCH(AI30,$AG$18:$AG$23,0)) -> 14953 | AL30: 5 | AM30: =AH22 -> 15026 | AN30: =AF22 -> Garden | AO30: {=IFERROR(INDEX($AN$26:$AN$31,SMALL(IF($AM$26:$AM$31=AP30,ROW($AM$26:$AM$31)-ROW($AM$26)+1),COUNTIF($AP$26:AP30, AP30))),"")} -> Bedroom | AP30: =LARGE($AM$26:$AM$31,AL30) -> 14840 | AQ30: =INDEX($AG$18:$AG$23,MATCH(AP30,$AH$18:$AH$23,0)) -> 15303
N31: {=SUM(IFERROR(N19:N30,0))} -> 8924 | O31: {=SUM(IFERROR(O19:O30,0))} -> 2902 | AE31: 6 | AF31: =AG23 -> 14101 | AG31: =AF23 -> Decor | AH31: {=IFERROR(INDEX($AG$26:$AG$31,SMALL(IF($AF$26:$AF$31=AI31,ROW($AF$26:$AF$31)-ROW($AF$26)+1),COUNTIF($AI$26:AI31, AI31))),"")} -> Garden | AI31: =LARGE($AF$26:$AF$31,AE31) -> 13453 | AJ31: =INDEX($AH$18:$AH$23,MATCH(AI31,$AG$18:$AG$23,0)) -> 15026 | AL31: 6 | AM31: =AH23 -> 14953 | AN31: =AF23 -> Decor | AO31: {=IFERROR(INDEX($AN$26:$AN$31,SMALL(IF($AM$26:$AM$31=AP31,ROW($AM$26:$AM$31)-ROW($AM$26)+1),COUNTIF($AP$26:AP31, AP31))),"")} -> Bathroom | AP31: =LARGE($AM$26:$AM$31,AL31) -> 13575 | AQ31: =INDEX($AG$18:$AG$23,MATCH(AP31,$AH$18:$AH$23,0)) -> 15376

Sheet Dashboard
A28: `
